......F...
======================================================================
FAIL: test_predict_1 (__main__.TestNetflix)
----------------------------------------------------------------------
Traceback (most recent call last):
  File "TestNetflix.py", line 58, in test_predict_1
    self.assert_(False)
AssertionError: False is not true

----------------------------------------------------------------------
Ran 10 tests in 2.282s

FAILED (failures=1)
TestNetflix.py
